Workbook

Sheet Pricing
A1: 1614 Home Co. — Pricing (source of truth, launch brief 2026-09-24)
A3: Standard — up to 3 baths | B3: 799
A4: Standard — 4 baths | B4: 899
A5: Standard — 5 baths | B5: 999
A6: Founding — up to 3 baths | B6: 699
A7: Founding — 4 baths | B7: 799
A8: Founding — 5 baths | B8: 899
A9: Custom review at bathrooms >= | B9: 6
A10: Additional HVAC system (per year) | B10: 150
A11: Additional water heater (per year) | B11: 40
A12: Member Setup base | B12: 199
A13: Additional standard leak sensor (beyond the 4 included in setup) | B13: 35
A14: Specialty / probe sensor | B14: 49
... A21: Water Defense conversion window (days) | B21: 30
A23: Blue = input from launch brief (Justin, 2026-09-24). Do not create new pricing here.
A24: Tier rule (Justin 2026-09-24): each full AND each half bathroom counts as one bathroom toward the tier. 2 full + 2 half = 4-bath tier.
A25: Sensor rule (Justin 2026-09-24): Member Setup $199 includes the hub + first 4 standard leak sensors. Enter only ADDITIONAL standard sensors beyond 4 (= max(total at home - 4, 0)). Specialty sensors are $49 each; a specialty sensor in one of the first 4 spots is $49 only.

Sheet Quote
A1: 1614 Home Co. — Quote Calculator (CURRENT 2026-09-24)
A2: Keep water where it belongs. Fill YELLOW cells only. Everything else is a formula.
A4: INPUTS
A5: Customer / address label | B5: TEST — Fake Customer (do not invoice)
A6: Full bathrooms | B6: 2
A7: Half bathrooms | B7: 1
A8: HVAC systems | B8: 2
A9: Water heaters | B9: 1
A10: Approx. square feet (blank if unknown) | B10: 2400
A11: Sump pump? (yes/no/blank) | B11: yes
A12: Quote a membership? (1=yes, 0=Water Defense only) | B12: 1
A13: Founding? (1/0) | B13: 1
A14: Additional Standard Sensors Beyond Included 4 (count; = max(total - 4, 0)) | B14: 3
A15: Specialty / Probe Sensors (count) | B15: 1
A16: Water Defense setup? (1/0) | B16: 0
A17: Water Defense conversion? (1/0) — setup completed within 30 days | B17: 0
A18: Boiler? (1/0) | B18: 0
A19: Well / pressure tank? (1/0) | B19: 0
A20: Unusual complexity? (1/0) | B20: 0
A21: Sales tax rate (fraction, e.g. 0.08; blank = not applied)
A22: Tax applies to (none / setup / all) | B22: none
A24: CALCULATION
A25: Bathroom count (full + half, each counts as one) | B25: =$B$6+$B$7
A26: Bathroom tier (3/4/5, 0 = custom review) | B26: =IF($B$25>=Pricing!$B$9,0,IF($B$25<=3,3,$B$25))
A27: Custom review required? (1/0) | B27: =IF(OR($B$26=0,AND($B$10<>"",$B$10>=Pricing!$B$20)),1,0)
A28: Membership base | B28: =IF(AND($B$12=1,$B$27=0),IF($B$13=1,CHOOSE($B$26-2,Pricing!$B$6,Pricing!$B$7,Pricing!$B$8),CHOOSE($B$26-2,Pricing!$B$3,Pricing!$B$4,Pricing!$B$5)),0)
A29: Additional HVAC adder | B29: =IF(AND($B$12=1,$B$27=0),MAX(0,$B$8-1)*Pricing!$B$10,0)
A30: Additional water heater adder | B30: =IF(AND($B$12=1,$B$27=0),MAX(0,$B$9-1)*Pricing!$B$11,0)
A31: Water Defense conversion credit (first-year membership) | B31: =IF(AND($B$17=1,$B$12=1,$B$27=0),-Pricing!$B$16,0)
A32: ANNUAL TOTAL, first year (membership + adders + conversion credit) | B32: =ROUND($B$28+$B$29+$B$30+$B$31,2)
A33: Member Setup base — includes hub + first 4 standard sensors (waived on Water Defense conversion) | B33: =IF(AND(AND($B$12=1,$B$27=0),NOT(AND($B$17=1,$B$12=1,$B$27=0))),Pricing!$B$12,0)
A34: Additional standard sensors beyond included 4 (× $35) | B34: =$B$14*Pricing!$B$13
A35: Specialty / probe sensors (× $49) | B35: =$B$15*Pricing!$B$14
A36: Water Defense setup (not charged again on conversion) | B36: =IF(AND($B$16=1,NOT(AND($B$17=1,$B$12=1,$B$27=0))),Pricing!$B$15,0)
A37: SETUP TOTAL (one time, upfront; conversion = new sensors/equipment only) | B37: =ROUND($B$33+$B$34+$B$35+$B$36,2)
A38: MONTHLY PAYMENT (annual × 1.08 ÷ 12, rounded to cents) | B38: =IF($B$32>0,ROUND($B$32*Pricing!$B$17/Pricing!$B$18,2),0)
A39: Monthly total over 12-month term | B39: =ROUND($B$38*Pricing!$B$18,2)
A40: Sales tax PLACEHOLDER (not a taxability determination) | B40: =IF(OR($B$21="",$B$22="none"),0,ROUND(IF($B$22="setup",$B$37,$B$32+$B$37)*$B$21,2))
A41: PAY ANNUALLY: due at signup (annual + setup + tax placeholder) | B41: =ROUND($B$32+$B$37+$B$40,2)
A43: FLAGS
...

Sheet Test Cases
A1: Expected results from quote_calculator.py — paste inputs into Quote sheet to spot-check
A3: Case | B3: Full | C3: Half | D3: HVAC | E3: WH | F3: Founding | G3: Addl std sensors (beyond 4) | H3: Spec sensors | I3: Water Def | J3: Conversion | K3: Expected annual | L3: Expected setup | M3: Expected monthly
A4: Std 2/1 baths | B4: 2 | C4: 1 | D4: 1 | E4: 1 | F4: 0 | G4: 0 | H4: 0 | I4: 0 | J4: 0 | K4: 799 | L4: 199 | M4: 71.91
A5: Std 4 baths | B5: 4 | C5: 0 | D5: 1 | E5: 1 | F5: 0 | G5: 0 | H5: 0 | I5: 0 | J5: 0 | K5: 899 | L5: 199 | M5: 80.91
A6: Std 5 baths | B6: 5 | C6: 0 | D6: 1 | E6: 1 | F6: 0 | G6: 0 | H6: 0 | I6: 0 | J6: 0 | K6: 999 | L6: 199 | M6: 89.91
A7: Founding 2/1 + 2 HVAC + 3 ADDITIONAL std + 1 spec (Scenario A) | B7: 2 | C7: 1 | D7: 2 | E7: 1 | F7: 1 | G7: 3 | H7: 1 | I7: 0 | J7: 0 | K7: 849 | L7: 353 | M7: 76.41
A8: Founding 2/1 + 2 HVAC + 3 TOTAL std (0 additional) + 1 spec | B8: 2 | C8: 1 | D8: 2 | E8: 1 | F8: 1 | G8: 0 | H8: 1 | I8: 0 | J8: 0 | K8: 849 | L8: 248 | M8: 76.41
A9: Founding 3/1 (tier 4) + 2 WH | B9: 3 | C9: 1 | D9: 1 | E9: 2 | F9: 1 | G9: 0 | H9: 0 | I9: 0 | J9: 0 | K9: 839 | L9: 199 | M9: 75.51
A10: Std 2 baths + Water Defense | B10: 2 | C10: 0 | D10: 1 | E10: 1 | F10: 0 | G10: 0 | H10: 0 | I10: 1 | J10: 0 | K10: 799 | L10: 448 | M10: 71.91
A11: Std 2/2 baths (4 bathrooms -> 4-bath tier) | B11: 2 | C11: 2 | D11: 1 | E11: 1 | F11: 0 | G11: 0 | H11: 0 | I11: 0 | J11: 0 | K11: 899 | L11: 199 | M11: 80.91
A12: Std 2/1 + WD conversion + 1 new std sensor | B12: 2 | C12: 1 | D12: 1 | E12: 1 | F12: 0 | G12: 1 | H12: 0 | I12: 0 | J12: 1 | K12: 749 | L12: 35 | M12: 67.41
A13: Founding 3/1 + 2 HVAC + WD conversion | B13: 3 | C13: 1 | D13: 2 | E13: 1 | F13: 1 | G13: 0 | H13: 0 | I13: 0 | J13: 1 | K13: 899 | L13: 0 | M13: 80.91
A14: WD conversion with WD box ticked (no double charge) | B14: 2 | C14: 0 | D14: 1 | E14: 1 | F14: 0 | G14: 0 | H14: 0 | I14: 1 | J14: 1 | K14: 749 | L14: 0 | M14: 67.41
A15: 6 baths -> custom review | B15: 6 | C15: 0 | D15: 1 | E15: 1 | F15: 0 | G15: 0 | H15: 0 | I15: 0 | J15: 0 | K15: 0 | L15: 0 | M15: 0
